Workbook

Sheet Анализ данных
A1: Блок 1. Описательная статистика: сброс загрязнённых сточных вод (млн м³)
A2: Количество регионов | B2: =COUNTA(clean_regions!A3:A87) -> 85 | D2: Исследовательские вопросы: 1. В каких регионах России фиксируется наибольший уровень загрязнения поверхностных вод? (лист "Топы и анти-топы") 2. Какие загрязняющие вещества представляют наибольшую угрозу? (Блок 5а) 3. Какие реки и водные бассейны страдают сильнее всего? (Блок 5б + топ бассейнов на листе лист "Топы и анти-топы") 4. Становится ли вода чище или грязнее? Тенденции за 30 лет. (Блок 5а + Блок 5б) 5. Существуют ли географические кластеры загрязнения? (Блок 3 + перекрестный анализ на листе "Топы и анти-топы") 6. Как тип региона (промышленный, аграрный, столичный) влияет на загрязнение воды? (Блок 4 + топ отраслей на листе "Топы и анти-топы")
A3: Сумма по РФ (млн м³) | B3: =SUM(clean_regions!F3:F87) -> 9017.24
A4: Среднее (млн м³) | B4: =ROUND(AVERAGE(clean_regions!F3:F87), 1) -> 106.1
A5: Медиана (млн м³) | B5: =ROUND(MEDIAN(clean_regions!F3:F87), 1) -> 65.5
A6: Мода (млн м³) | B6: =MODE(clean_regions!F3:F87) -> 128
A7: Минимум (млн м³) | B7: =MIN(clean_regions!F3:F87) -> 0
A8: Регион-минимум | B8: {=INDEX(clean_regions!A3:A87, MATCH(MIN(clean_regions!F3:F87), clean_regions!F3:F87, 0))} -> Ненецкий автономный округ
A9: Максимум (млн м³) | B9: =MAX(clean_regions!F3:F87) -> 937.5
A10: Регион-максимум | B10: {=INDEX(clean_regions!A3:A87, MATCH(MAX(clean_regions!F3:F87), clean_regions!F3:F87, 0))} -> Санкт-Петербург
A11: Размах | B11: =ROUND(B9-B7, 1) -> 937.5
A12: Стандартное отклонение | B12: =ROUND(STDEV(clean_regions!F3:F87), 1) -> 135.7
A14: Блок 2. Описательная статистика: сброс на душу населения (м³ на чел.)
A15: Среднее | B15: =ROUND(AVERAGE(clean_regions!J3:J87), 1) -> 64.4
A16: Медиана | B16: =ROUND(MEDIAN(clean_regions!J3:J87), 1) -> 53.8
A17: Минимум | B17: =MIN(clean_regions!J3:J87) -> 0
A18: Регион-минимум | B18: {=INDEX(clean_regions!A3:A87, MATCH(MIN(clean_regions!J3:J87), clean_regions!J3:J87, 0))} -> Ненецкий автономный округ
A19: Максимум | B19: =MAX(clean_regions!J3:J87) -> 241.9
A20: Регион-максимум | B20: {=INDEX(clean_regions!A3:A87, MATCH(MAX(clean_regions!J3:J87), clean_regions!J3:J87, 0))} -> Архангельская область
A22: Блок 3. Сравнение по федеральным округам Вопрос 5. Есть ли устойчивые “кластеры” загрязнения (группы регионов с похожими проблемами)?
A23: Округ | B23: Сумма сброса, млн м³ | C23: Средний сброс, млн м³ | D23: Средний на душу, м³/чел. | E23: Кол-во регионов | F23: Доля от РФ, %
A24: ЦФО | B24: =SUMIFS(clean_regions!F3:F87,clean_regions!B3:B87,"ЦФО") -> 1510.9 | C24: =ROUND(AVERAGEIFS(clean_regions!F3:F87,clean_regions!B3:B87,"ЦФО"),1) -> 83.9 | D24: =ROUND(AVERAGEIFS(clean_regions!J3:J87,clean_regions!B3:B87,"ЦФО"),1) -> 51.8 | E24: =COUNTIF(clean_regions!B3:B87,"ЦФО") -> 18 | F24: =ROUND(B24/SUM($B$24:$B$31)*100, 1) -> 16.8
A25: СЗФО | B25: =SUMIFS(clean_regions!F3:F87,clean_regions!B3:B87,"СЗФО") -> 1967.7 | C25: =ROUND(AVERAGEIFS(clean_regions!F3:F87,clean_regions!B3:B87,"СЗФО"),1) -> 178.9 | D25: =ROUND(AVERAGEIFS(clean_regions!J3:J87,clean_regions!B3:B87,"СЗФО"),1) -> 112.2 | E25: =COUNTIF(clean_regions!B3:B87,"СЗФО") -> 11 | F25: =ROUND(B25/SUM($B$24:$B$31)*100, 1) -> 21.8
A26: ЮФО | B26: =SUMIFS(clean_regions!F3:F87,clean_regions!B3:B87,"ЮФО") -> 601.24 | C26: =ROUND(AVERAGEIFS(clean_regions!F3:F87,clean_regions!B3:B87,"ЮФО"),1) -> 75.2 | D26: =ROUND(AVERAGEIFS(clean_regions!J3:J87,clean_regions!B3:B87,"ЮФО"),1) -> 33.7 | E26: =COUNTIF(clean_regions!B3:B87,"ЮФО") -> 8 | F26: =ROUND(B26/SUM($B$24:$B$31)*100, 1) -> 6.7
A27: СКФО | B27: =SUMIFS(clean_regions!F3:F87,clean_regions!B3:B87,"СКФО") -> 272.1 | C27: =ROUND(AVERAGEIFS(clean_regions!F3:F87,clean_regions!B3:B87,"СКФО"),1) -> 38.9 | D27: =ROUND(AVERAGEIFS(clean_regions!J3:J87,clean_regions!B3:B87,"СКФО"),1) -> 40.3 | E27: =COUNTIF(clean_regions!B3:B87,"СКФО") -> 7 | F27: =ROUND(B27/SUM($B$24:$B$31)*100, 1) -> 3
A28: ПФО | B28: =SUMIFS(clean_regions!F3:F87,clean_regions!B3:B87,"ПФО") -> 1742.4 | C28: =ROUND(AVERAGEIFS(clean_regions!F3:F87,clean_regions!B3:B87,"ПФО"),1) -> 124.5 | D28: =ROUND(AVERAGEIFS(clean_regions!J3:J87,clean_regions!B3:B87,"ПФО"),1) -> 56.9 | E28: =COUNTIF(clean_regions!B3:B87,"ПФО") -> 14 | F28: =ROUND(B28/SUM($B$24:$B$31)*100, 1) -> 19.3
A29: УФО | B29: =SUMIFS(clean_regions!F3:F87,clean_regions!B3:B87,"УФО") -> 976.1 | C29: =ROUND(AVERAGEIFS(clean_regions!F3:F87,clean_regions!B3:B87,"УФО"),1) -> 162.7 | D29: =ROUND(AVERAGEIFS(clean_regions!J3:J87,clean_regions!B3:B87,"УФО"),1) -> 70.8 | E29: =COUNTIF(clean_regions!B3:B87,"УФО") -> 6 | F29: =ROUND(B29/SUM($B$24:$B$31)*100, 1) -> 10.8
A30: СФО | B30: =SUMIFS(clean_regions!F3:F87,clean_regions!B3:B87,"СФО") -> 1286.3 | C30: =ROUND(AVERAGEIFS(clean_regions!F3:F87,clean_regions!B3:B87,"СФО"),1) -> 128.6 | D30: =ROUND(AVERAGEIFS(clean_regions!J3:J87,clean_regions!B3:B87,"СФО"),1) -> 66.9 | E30: =COUNTIF(clean_regions!B3:B87,"СФО") -> 10 | F30: =ROUND(B30/SUM($B$24:$B$31)*100, 1) -> 14.3
A31: ДФО | B31: =SUMIFS(clean_regions!F3:F87,clean_regions!B3:B87,"ДФО") -> 660.5 | C31: =ROUND(AVERAGEIFS(clean_regions!F3:F87,clean_regions!B3:B87,"ДФО"),1) -> 60 | D31: =ROUND(AVERAGEIFS(clean_regions!J3:J87,clean_regions!B3:B87,"ДФО"),1) -> 78.6 | E31: =COUNTIF(clean_regions!B3:B87,"ДФО") -> 11 | F31: =ROUND(B31/SUM($B$24:$B$31)*100, 1) -> 7.3
A33: 1. СЗФО - лидер и по среднему сбросу на регион (178.9 млн м³), и по среднему сбросу на душу населения (112.2 м³/чел.). Это главный кластер загрязнения в России. Возможные причины: Санкт-Петербург, целлюлозно-бумажные комбинаты Архангельской области 2. ПФО второй по суммарному сбросу (1742.4 млн м³), но на душу населения (56.9 м³/чел.) - середина. Загрязнение «размывается» большим населением Поволжья. Основные загрязнители: Самарская, Нижегородская области, Татарстан, Башкортостан. 3. УФО при всего 6 регионах имеет второй по величине средний сброс (162.7 млн м³) и высокий показатель на душу (70.8 м³/чел.). Это кластер тяжелой промышленности: Свердловская область (501.3 млн м³) и Челябинская (271.5 млн м³) дают основной вклад. 4. ДФО занимает 3-е место по сбросу на душу населения (78.6 м³/чел.) при низком суммарном сбросе. Причина: малое население при наличии крупных промышленных центров: Приморский край, Хабаровск 5. ЮФО и СКФО - самые чистые округа: минимальный показатель на душу (33.7 и 40.3 м³/чел.). Преобладает сельское хозяйство, мало тяжелой промышленности. 6. Три кластера загрязнения: «Северо-Западный» (СЗФО, 112.2 м³/чел. - ЦБК и мегаполис), «Уральский» (УрФО, 70.8 м³/чел. - металлургия), «Дальневосточный» (ДФО, 78.6 м³/чел. - малое население + промышленность).
A35: Блок 4. Доля отраслей в загрязнении Вопрос 6. Как тип региона и отрасль экономики влияют на загрязнение воды?
A36: Отрасль | B36: Сброс 2022, млн м³ | C36: Доля, %
A37: Водоснабжение и водоотведение | B37: 7406.3 | C37: =ROUND(B37/SUM(B37:B42)*100, 1) -> 65.4
A38: Обрабатывающие производства | B38: 1704.9 | C38: =ROUND(B38/SUM(B37:B42)*100, 1) -> 15.1
A39: Энергетика | B39: 804.6 | C39: =ROUND(B39/SUM(B37:B42)*100, 1) -> 7.1
A40: Сельское хозяйство | B40: 763.8 | C40: =ROUND(B40/SUM(B37:B42)*100, 1) -> 6.7
A41: Добыча полезных ископаемых | B41: 404 | C41: =ROUND(B41/SUM(B37:B42)*100, 1) -> 3.6
A42: Прочие | B42: 242.2 | C42: =ROUND(B42/SUM(B37:B42)*100, 1) -> 2.1
A44: >65% загрязнённых стоков - это бытовые и городские стоки (ЖКХ), а не промышленность напрямую, значит, главная проблема - изношенные очистные сооружения в городах, а не заводские трубы.
A46: Блок 5. Динамика загрязнения 1993-2022 гг. Вопрос 2. Какие загрязняющие вещества представляют наибольшую угрозу? Вопрос 3. Какие реки и водные бассейны страдают сильнее всего? Вопрос 4. Становится ли вода чище или грязнее? Тенденции за 30 лет.
...

Sheet Топы и анти-топы
A1: Топ-15 регионов по объему сброса загрязнённых сточных вод (м³ на чел.), 2024 | G1: Топ-15 регионов по сбросу загрязнённых вод на душу населения (м³ на чел.), 2024 | N1: Регионы, попавшие в несколько топов одновременно (перекрёстный анализ)
A2: Место | B2: Субъект РФ | C2: Федеральный округ | D2: Сброс загрязн., млн м3 | E2: Доля загрязн процент | G2: Место | H2: Субъект РФ | I2: Федеральный округ | J2: Сброс загрязн., млн м³ | K2: Население, тыс. чел. | L2: Сброс на душу, м³ | N2: Субъект РФ | O2: Топ по сбросу | P2: Топ на душу | Q2: Топ по случаям | R2: Топ по доле | S2: Число совпадений
A3: 1 | B3: Санкт-Петербург | C3: СЗФО | D3: 937.5 | E3: 84.6 | G3: 1 | H3: Архангельская область | I3: СЗФО | J3: 254.5 | K3: 1052 | L3: 241.9 | N3: Свердловская область | O3: =IF(COUNTIF(B3:B17,N3)>0,"да","нет") -> да | P3: =IF(COUNTIF(H3:H17,N3)>0,"да","нет") -> да | Q3: =IF(COUNTIF(B41:B50,N3)>0,"да","нет") -> да | R3: =IF(COUNTIF(H41:H50,N3)>0,"да","нет") -> нет | S3: =COUNTIF(O3:R3,"да") -> 3
A4: 2 | B4: Свердловская область | C4: УФО | D4: 501.3 | E4: 75 | G4: 2 | H4: Иркутская область | I4: СФО | J4: 472 | K4: 2344 | L4: 201.4 | N4: Санкт-Петербург | O4: =IF(COUNTIF(B3:B17,N4)>0,"да","нет") -> да | P4: =IF(COUNTIF(H3:H17,N4)>0,"да","нет") -> да | Q4: =IF(COUNTIF(B41:B50,N4)>0,"да","нет") -> нет | R4: =IF(COUNTIF(H41:H50,N4)>0,"да","нет") -> нет | S4: =COUNTIF(O4:R4,"да") -> 2
A5: 3 | B5: Иркутская область | C5: СФО | D5: 472 | E5: 47.5 | G5: 3 | H5: Республика Карелия | I5: СЗФО | J5: 117.1 | K5: 587 | L5: 199.5 | N5: Иркутская область | O5: =IF(COUNTIF(B3:B17,N5)>0,"да","нет") -> да | P5: =IF(COUNTIF(H3:H17,N5)>0,"да","нет") -> да | Q5: =IF(COUNTIF(B41:B50,N5)>0,"да","нет") -> нет | R5: =IF(COUNTIF(H41:H50,N5)>0,"да","нет") -> нет | S5: =COUNTIF(O5:R5,"да") -> 2
A6: 4 | B6: Самарская область | C6: ПФО | D6: 346.4 | E6: 86.1 | G6: 4 | H6: Мурманская область | I6: СЗФО | J6: 128 | K6: 674 | L6: 189.9 | N6: Самарская область | O6: =IF(COUNTIF(B3:B17,N6)>0,"да","нет") -> да | P6: =IF(COUNTIF(H3:H17,N6)>0,"да","нет") -> да | Q6: =IF(COUNTIF(B41:B50,N6)>0,"да","нет") -> нет | R6: =IF(COUNTIF(H41:H50,N6)>0,"да","нет") -> да | S6: =COUNTIF(O6:R6,"да") -> 3
A7: 5 | B7: Нижегородская область | C7: ПФО | D7: 313.7 | E7: 38 | G7: 5 | H7: Санкт-Петербург | I7: СЗФО | J7: 937.5 | K7: 5600 | L7: 167.4 | N7: Челябинская область | O7: =IF(COUNTIF(B3:B17,N7)>0,"да","нет") -> да | P7: =IF(COUNTIF(H3:H17,N7)>0,"да","нет") -> нет | Q7: =IF(COUNTIF(B41:B50,N7)>0,"да","нет") -> да | R7: =IF(COUNTIF(H41:H50,N7)>0,"да","нет") -> нет | S7: =COUNTIF(O7:R7,"да") -> 2
A8: 6 | B8: Красноярский край | C8: СФО | D8: 283.6 | E8: 15.5 | G8: 6 | H8: Томская область | I8: СФО | J8: 142.5 | K8: 1063 | L8: 134.1 | N8: Красноярский край | O8: =IF(COUNTIF(B3:B17,N8)>0,"да","нет") -> да | P8: =IF(COUNTIF(H3:H17,N8)>0,"да","нет") -> нет | Q8: =IF(COUNTIF(B41:B50,N8)>0,"да","нет") -> да | R8: =IF(COUNTIF(H41:H50,N8)>0,"да","нет") -> нет | S8: =COUNTIF(O8:R8,"да") -> 2
A9: 7 | B9: Московская область | C9: ЦФО | D9: 272.2 | E9: 22.6 | G9: 7 | H9: Ленинградская область | I9: СЗФО | J9: 269.8 | K9: 2076 | L9: 130 | N9: Московская область | O9: =IF(COUNTIF(B3:B17,N9)>0,"да","нет") -> да | P9: =IF(COUNTIF(H3:H17,N9)>0,"да","нет") -> нет | Q9: =IF(COUNTIF(B41:B50,N9)>0,"да","нет") -> да | R9: =IF(COUNTIF(H41:H50,N9)>0,"да","нет") -> нет | S9: =COUNTIF(O9:R9,"да") -> 2
A10: 8 | B10: Челябинская область | C10: УФО | D10: 271.5 | E10: 37.1 | G10: 8 | H10: Хабаровский край | I10: ДФО | J10: 164.3 | K10: 1289 | L10: 127.5 | N10: Архангельская область | O10: =IF(COUNTIF(B3:B17,N10)>0,"да","нет") -> да | P10: =IF(COUNTIF(H3:H17,N10)>0,"да","нет") -> да | Q10: =IF(COUNTIF(B41:B50,N10)>0,"да","нет") -> нет | R10: =IF(COUNTIF(H41:H50,N10)>0,"да","нет") -> нет | S10: =COUNTIF(O10:R10,"да") -> 2
A11: 9 | B11: Ленинградская область | C11: СЗФО | D11: 269.8 | E11: 7.3 | G11: 9 | H11: Республика Северная Осетия | I11: СКФО | J11: 87 | K11: 687 | L11: 126.6 | N11: Мурманская область | O11: =IF(COUNTIF(B3:B17,N11)>0,"да","нет") -> нет | P11: =IF(COUNTIF(H3:H17,N11)>0,"да","нет") -> да | Q11: =IF(COUNTIF(B41:B50,N11)>0,"да","нет") -> да | R11: =IF(COUNTIF(H41:H50,N11)>0,"да","нет") -> нет | S11: =COUNTIF(O11:R11,"да") -> 2
A12: 10 | B12: Архангельская область | C12: СЗФО | D12: 254.5 | E12: 42.9 | G12: 10 | H12: Ярославская область | I12: ЦФО | J12: 145.8 | K12: 1221 | L12: 119.4 | N12: Омская область | O12: =IF(COUNTIF(B3:B17,N12)>0,"да","нет") -> нет | P12: =IF(COUNTIF(H3:H17,N12)>0,"да","нет") -> нет | Q12: =IF(COUNTIF(B41:B50,N12)>0,"да","нет") -> да | R12: =IF(COUNTIF(H41:H50,N12)>0,"да","нет") -> да | S12: =COUNTIF(O12:R12,"да") -> 2
A13: 11 | B13: Приморский край | C13: ДФО | D13: 201 | E13: 59 | G13: 11 | H13: Свердловская область | I13: УрФО | J13: 501.3 | K13: 4267 | L13: 117.5 | N13: Ярославская область | O13: =IF(COUNTIF(B3:B17,N13)>0,"да","нет") -> нет | P13: =IF(COUNTIF(H3:H17,N13)>0,"да","нет") -> да | Q13: =IF(COUNTIF(B41:B50,N13)>0,"да","нет") -> нет | R13: =IF(COUNTIF(H41:H50,N13)>0,"да","нет") -> да | S13: =COUNTIF(O13:R13,"да") -> 2
A14: 12 | B14: Москва | C14: ЦФО | D14: 198.5 | E14: 18.6 | G14: 12 | H14: Самарская область | I14: ПФО | J14: 346.4 | K14: 3131 | L14: 110.6 | N14: Приморский край | O14: =IF(COUNTIF(B3:B17,N14)>0,"да","нет") -> да | P14: =IF(COUNTIF(H3:H17,N14)>0,"да","нет") -> да | Q14: =IF(COUNTIF(B41:B50,N14)>0,"да","нет") -> нет | R14: =IF(COUNTIF(H41:H50,N14)>0,"да","нет") -> нет | S14: =COUNTIF(O14:R14,"да") -> 2
A15: 13 | B15: Ростовская область | C15: ЮФО | D15: 196.5 | E15: 15.1 | G15: 13 | H15: Приморский край | I15: ДФО | J15: 201 | K15: 1820 | L15: 110.4 | N15: Ханты-Мансийский АО | O15: =IF(COUNTIF(B3:B17,N15)>0,"да","нет") -> нет | P15: =IF(COUNTIF(H3:H17,N15)>0,"да","нет") -> нет | Q15: =IF(COUNTIF(B41:B50,N15)>0,"да","нет") -> да | R15: =IF(COUNTIF(H41:H50,N15)>0,"да","нет") -> нет | S15: =COUNTIF(O15:R15,"да") -> 1
A16: 14 | B16: Республика Татарстан | C16: ПФО | D16: 195.2 | E16: 37.7 | G16: 14 | H16: Камчатский край | I16: ДФО | J16: 31.5 | K16: 291 | L16: 108.2 | N16: Ямало-Ненецкий АО | O16: =IF(COUNTIF(B3:B17,N16)>0,"да","нет") -> нет | P16: =IF(COUNTIF(H3:H17,N16)>0,"да","нет") -> нет | Q16: =IF(COUNTIF(B41:B50,N16)>0,"да","нет") -> да | R16: =IF(COUNTIF(H41:H50,N16)>0,"да","нет") -> нет | S16: =COUNTIF(O16:R16,"да") -> 1
A17: 15 | B17: Республика Башкортостан | C17: ПФО | D17: 169.8 | E17: 36.2 | G17: 15 | H17: Магаданская область | I17: ДФО | J17: 14.4 | K17: 136 | L17: 105.9 | N17: Курганская область | O17: =IF(COUNTIF(B3:B17,N17)>0,"да","нет") -> нет | P17: =IF(COUNTIF(H3:H17,N17)>0,"да","нет") -> нет | Q17: =IF(COUNTIF(B41:B50,N17)>0,"да","нет") -> нет | R17: =IF(COUNTIF(H41:H50,N17)>0,"да","нет") -> да | S17: =COUNTIF(O17:R17,"да") -> 1
N18: Москва | O18: =IF(COUNTIF(B3:B17,N18)>0,"да","нет") -> да | P18: =IF(COUNTIF(H3:H17,N18)>0,"да","нет") -> нет | Q18: =IF(COUNTIF(B41:B50,N18)>0,"да","нет") -> да | R18: =IF(COUNTIF(H41:H50,N18)>0,"да","нет") -> нет | S18: =COUNTIF(O18:R18,"да") -> 2
N19: Нижегородская область | O19: =IF(COUNTIF(B3:B17,N19)>0,"да","нет") -> да | P19: =IF(COUNTIF(H3:H17,N19)>0,"да","нет") -> нет | Q19: =IF(COUNTIF(B41:B50,N19)>0,"да","нет") -> нет | R19: =IF(COUNTIF(H41:H50,N19)>0,"да","нет") -> нет | S19: =COUNTIF(O19:R19,"да") -> 1
A20: Анти-топ-15: регионы с наименьшим сбросом загрязнённых сточных вод, 2024 | G20: Анти-топ-15: регионы с наименьшим сбросом загрязнённых вод на душу населения, 2024
A21: Место | B21: Субъект РФ | C21: Федеральный округ | D21: Сброс загрязн., млн м³ | E21: Доля загрязн., % | G21: Место | H21: Субъект РФ | I21: Федеральный округ | J21: Сброс загрязн., млн м³ | K21: Население, тыс. чел. | L21: Сброс на душу, м³
A22: 1 | B22: Чеченская Республика | C22: СКФО | D22: 0 | E22: 0 | G22: 46054 | H22: Чеченская Республика | I22: СКФО | J22: 0 | K22: 1541 | L22: 0
A23: 2 | B23: Ненецкий автономный округ | C23: СЗФО | D23: 0 | E23: 0 | G23: 46054 | H23: Ненецкий автономный округ | I23: СЗФО | J23: 0 | K23: 45 | L23: 0
A24: 3 | B24: Республика Алтай | C24: СФО | D24: 0.4 | E24: 13.1 | G24: 3 | H24: Республика Ингушетия | I24: СКФО | J24: 0.6 | K24: 524 | L24: 1.1
A25: 4 | B25: Республика Ингушетия | C25: СКФО | D25: 0.6 | E25: 24.5 | G25: 4 | H25: Республика Алтай | I25: СФО | J25: 0.4 | K25: 211 | L25: 1.9
A26: 5 | B26: Республика Адыгея | C26: ЮФО | D26: 1.3 | E26: 1 | G26: 5 | H26: Республика Дагестан | I26: СКФО | J26: 7.5 | K26: 3182 | L26: 2.4
A27: 6 | B27: Чукотский автономный округ | C27: ДФО | D27: 2.9 | E27: 2.9 | G27: 6 | H27: Республика Адыгея | I27: ЮФО | J27: 1.3 | K27: 497 | L27: 2.6
A28: 7 | B28: Республика Мордовия | C28: ПФО | D28: 5 | E28: 16.4 | G28: 7 | H28: Алтайский край | I28: СФО | J28: 13.2 | K28: 2268 | L28: 5.8
A29: 8 | B29: Республика Тыва | C29: СФО | D29: 7.1 | E29: 53.3 | G29: 8 | H29: Республика Мордовия | I29: ПФО | J29: 5 | K29: 764 | L29: 6.5
A30: 9 | B30: Республика Дагестан | C30: СКФО | D30: 7.5 | E30: 2.2 | G30: 9 | H30: Москва | I30: ЦФО | J30: 198.5 | K30: 13104 | L30: 15.2
A31: 10 | B31: Республика Калмыкия | C31: ЮФО | D31: 9.1 | E31: 75 | G31: 10 | H31: Ивановская область | I31: ЦФО | J31: 16.2 | K31: 946 | L31: 17.1
A32: 11 | B32: Еврейская автономная область | C32: ДФО | D32: 11.7 | E32: 87.3 | G32: 11 | H32: Республика Тыва | I32: СФО | J32: 7.1 | K32: 337 | L32: 21.1
A33: 12 | B33: Алтайский край | C33: СФО | D33: 13.2 | E33: 3.7 | G33: 12 | H33: Кабардино-Балкарская Республика | I33: СКФО | J33: 20.5 | K33: 907 | L33: 22.6
... A36: 15 | B36: Новгородская область | C36: СЗФО | D36: 17.6 | E36: 23.7 | G36: 15 | H36: Краснодарский край | I36: ЮФО | J36: 158.5 | K36: 5976 | L36: 26.5
A39: Топ-10 регионов по итоговому числу случаев высокого и экстремально высокого загрязнения водных объектов, I полугодие 2022 | G39: Топ-10 регионов по доле загрязнённых вод в общем объёме сброса (%), 2024 | N39: Топ бассейнов рек и морей по объёму сброса загрязнённых сточных вод, 2022 | S39: Топ отраслей по сбросу загрязнённых сточных вод, 2022
A40: Место | B40: Субъект РФ | C40: Высокое загрязнение | D40: Экстремально высокое | E40: Итого случаев | G40: Место | H40: Субъект РФ | I40: Федеральный округ | J40: Сброс всего, млн м³ | K40: Сброс загрязн., млн м³ | L40: Доля, % | N40: Место | O40: Бассейн | P40: Сброс 2022, млрд м³ | Q40: Доля от общего, % | S40: Место | T40: Отрасль | U40: Сброс 2017, млн м³ | V40: Сброс 2022, млн м³ | W40: Доля, % | X40: Изменение от 2017 к 2022, %
A41: 1 | B41: Свердловская область | C41: 250 | D41: 54 | E41: 304 | G41: 1 | H41: Курганская область | I41: УрФО | J41: 31.5 | K41: 31.4 | L41: 99.7 | N41: 1 | O41: Волга | P41: 4,3 | Q41: =ROUND(P41/11.3*100, 1) -> 38.1 | S41: 1 | T41: Водоснабжение и водоотведение | U41: 8251.7 | V41: 7406.3 | W41: 65.4 | X41: =ROUND((V41-U41)/U41*100, 1) -> -10.2
A42: 2 | B42: Московская область | C42: 115 | D42: 0 | E42: 115 | G42: 2 | H42: Омская область | I42: СФО | J42: 132.9 | K42: 124.8 | L42: 93.9 | N42: 2 | O42: Балтийское море | P42: 1,5 | Q42: =ROUND(P42/11.3*100, 1) -> 13.3 | S42: 2 | T42: Обрабатывающие производства | U42: 2402.6 | V42: 1704.9 | W42: 15.1 | X42: =ROUND((V42-U42)/U42*100, 1) -> -29
A43: 3 | B43: Мурманская область | C43: 85 | D43: 22 | E43: 107 | G43: 3 | H43: Владимирская область | I43: ЦФО | J43: 96 | K43: 89.8 | L43: 93.6 | N43: 3 | O43: Обь | P43: 1,4 | Q43: =ROUND(P43/11.3*100, 1) -> 12.4 | S43: 3 | T43: Энергетика | U43: 1001.1 | V43: 804.6 | W43: 7.1 | X43: =ROUND((V43-U43)/U43*100, 1) -> -19.6
A44: 46146 | B44: Новосибирская область | C44: 34 | D44: 17 | E44: 51 | G44: 4 | H44: Ярославская область | I44: ЦФО | J44: 159.7 | K44: 145.8 | L44: 91.3 | N44: 4 | O44: Кубань | P44: 0,9 | Q44: =ROUND(P44/11.3*100, 1) -> 8 | S44: 4 | T44: Сельское хозяйство | U44: 740.2 | V44: 763.8 | W44: 6.7 | X44: =ROUND((V44-U44)/U44*100, 1) -> 3.2
...

Sheet raw_regions
A1: Сброс сточных вод по субъектам РФ, 2024 г.
A2: Субъект РФ | B2: Федеральный округ | C2: Забор воды (млн м3) | D2: Потери воды (млн м3) | E2: Сброс всего (млн м3) | F2: Сброс загрязн (млн м3) | G2: Доля загрязн процент
A3: Белгородская область | B3: ЦФО | C3: 261.8 | D3: 46158 | E3: 125.6 | F3: 50.9 | G3: 40.6
A4: Брянская область | B4: ЦФО | C4: 106.5 | D4: 13.0 | E4: 62.8 | F4: 53.4 | G4: 85.1
A5: Владимирская область | B5: ЦФО | C5: 153.6 | D5: 15.0 | E5: 96.0 | F5: 89.8 | G5: 93.6
A6: Воронежская область | B6: ЦФО | C6: 459.4 | D6: 46098 | E6: 216.3 | F6: 128.0 | G6: 59.2
A7: Ивановская область | B7: ЦФО | C7: 101.0 | D7: 46068 | E7: 79.2 | F7: 46069 | G7: 46162
A8: Калужская область | B8: ЦФО | C8: 137.2 | D8: 46257 | E8: 85.8 | F8: 73.6 | G8: 85.7
A9: Костромская область | B9: ЦФО | C9: 1580.8 | D9: 46273 | E9: 1577.4 | F9: 32.8 | G9: 46024
A10: Курская область | B10: ЦФО | C10: 215.1 | D10: 46149 | E10: 83.6 | F10: 33.7 | G10: 40.4
A11: Липецкая область | B11: ЦФО | C11: 217.1 | D11: 33.4 | E11: 72.7 | F11: 53.3 | G11: 73.4
A12: Московская область | B12: ЦФО | C12: 326254 | D12: 350.0 | E12: 1207.0 | F12: 272.2 | G12: 46195
A13: Орловская область | B13: ЦФО | C13: 77.4 | D13: 46150 | E13: 49.3 | F13: 44.0 | G13: 89.1
A14: Рязанская область | B14: ЦФО | C14: 164.8 | D14: 46147 | E14: 118.3 | F14: 46228 | G14: 46224
A15: Смоленская область | B15: ЦФО | C15: 152.7 | D15: 46093 | E15: 66.0 | F15: 48.4 | G15: 73.2
A16: Тамбовская область | B16: ЦФО | C16: 122.5 | D16: 46089 | E16: 54.9 | F16: 44.3 | G16: 80.6
A17: Тверская область | B17: ЦФО | C17: 1290.2 | D17: 46291 | E17: 1177.9 | F17: 77.2 | G17: 46179
A18: Тульская область | B18: ЦФО | C18: 290.4 | D18: 65.1 | E18: 157.4 | F18: 123.1 | G18: 78.2
A19: Ярославская область | B19: ЦФО | C19: 196.6 | D19: 46130 | E19: 159.7 | F19: 145.8 | G19: 91.3
A20: Москва | B20: ЦФО | C20: 703.6 | D20: 46143 | E20: 1066.9 | F20: 198.5 | G20: 46191
A21: Республика Карелия | B21: СЗФО | C21: 191.7 | D21: 46179 | E21: 252.3 | F21: 117.1 | G21: 46.4
A22: Республика Коми | B22: СЗФО | C22: 469.8 | D22: 46091 | E22: 423.5 | F22: 61.1 | G22: 46126
A23: Ненецкий автономный округ | B23: СЗФО | C23: 46132 | D23: 0.3 | E23: 46204 | F23: 0.0 | G23: 0.0
A24: Архангельская область | B24: СЗФО | C24: 490.8 | D24: 46130 | E24: 593.8 | F24: 254.5 | G24: 42.9
A25: Вологодская область | B25: СЗФО | C25: 230.1 | D25: 46244 | E25: 195.8 | F25: 61.9 | G25: 31.6
A26: Калининградская область | B26: СЗФО | C26: 122.0 | D26: 46270 | E26: 117.0 | F26: 85.9 | G26: 73.4
A27: Ленинградская область | B27: СЗФО | C27: 680539 | D27: 40.0 | E27: 651350 | F27: 269.8 | G27: 46088
A28: Мурманская область | B28: СЗФО | C28: 1617.3 | D28: 46183 | E28: 1688.4 | F28: 128.0 | G28: 46180
A29: Новгородская область | B29: СЗФО | C29: 105.8 | D29: 46186 | E29: 74.3 | F29: 46190 | G29: 46226
A30: Псковская область | B30: СЗФО | C30: 117.1 | D30: 46146 | E30: 107.0 | F30: 34.3 | G30: 32.0
A31: Санкт-Петербург | B31: СЗФО | C31: 935.0 | D31: 58.5 | E31: 1108.3 | F31: 937.5 | G31: 84.6
A32: Республика Адыгея | B32: ЮФО | C32: 168.8 | D32: 46095 | E32: 126.0 | F32: 46082 | G32: 1.0
A33: Республика Калмыкия | B33: ЮФО | C33: 319.8 | D33: 126.2 | E33: 46065 | F33: 9.14 | G33: 75.0
A34: Республика Крым | B34: ЮФО | C34: 301.8 | D34: 97.0 | E34: 104.2 | F34: 95.1 | G34: 91.3
A35: Краснодарский край | B35: ЮФО | C35: 781042 | D35: 945.0 | E35: 546221 | F35: 158.5 | G35: 46207
A36: Астраханская область | B36: ЮФО | C36: 945.6 | D36: 143.2 | E36: 225.2 | F36: 34.4 | G36: 46096
A37: Волгоградская область | B37: ЮФО | C37: 907.7 | D37: 153.7 | E37: 124.8 | F37: 84.1 | G37: 67.4
A38: Ростовская область | B38: ЮФО | C38: 3455.0 | D38: 639.5 | E38: 1303.1 | F38: 196.5 | G38: 46037
A39: Севастополь | B39: ЮФО | C39: 54.1 | D39: 46219 | E39: 46292 | F39: 46075 | G39: 79.4
A40: Республика Дагестан | B40: СКФО | C40: 1192.7 | D40: 593.4 | E40: 345.0 | F40: 46149 | G40: 46055
...

Sheet clean_regions
A1: ОЧИЩЕННЫЕ ДАННЫЕ. Сброс сточных вод по субъектам РФ, 2024 г.
A2: Субъект РФ | B2: Федеральный округ | C2: Забор воды, млн м3 | D2: Потери воды, млн м3 | E2: Сброс всего, млн м3 | F2: Сброс загрязн., млн м3 | G2: Доля загрязн процент | I2: Население, тыс. чел. | J2: Сброс на душу, м3
A3: Белгородская область | B3: ЦФО | C3: 261.8 | D3: 16.5 | E3: 125.6 | F3: 50.9 | G3: 40.6 | I3: 1524 | J3: =ROUND(F3/I3*1000, 1) -> 33.4
A4: Брянская область | B4: ЦФО | C4: 106.5 | D4: 13 | E4: 62.8 | F4: 53.4 | G4: 85.1 | I4: 1156 | J4: =ROUND(F4/I4*1000, 1) -> 46.2
A5: Владимирская область | B5: ЦФО | C5: 153.6 | D5: 15 | E5: 96 | F5: 89.8 | G5: 93.6 | I5: 1318 | J5: =ROUND(F5/I5*1000, 1) -> 68.1
A6: Воронежская область | B6: ЦФО | C6: 459.4 | D6: 17.3 | E6: 216.3 | F6: 128 | G6: 59.2 | I6: 2287 | J6: =ROUND(F6/I6*1000, 1) -> 56
A7: Ивановская область | B7: ЦФО | C7: 101 | D7: 15.2 | E7: 79.2 | F7: 16.2 | G7: 20.5 | I7: 946 | J7: =ROUND(F7/I7*1000, 1) -> 17.1
A8: Калужская область | B8: ЦФО | C8: 137.2 | D8: 23.8 | E8: 85.8 | F8: 73.6 | G8: 85.7 | I8: 1000 | J8: =ROUND(F8/I8*1000, 1) -> 73.6
A9: Костромская область | B9: ЦФО | C9: 1580.8 | D9: 8.9 | E9: 1577.4 | F9: 32.8 | G9: 2.1 | I9: 602 | J9: =ROUND(F9/I9*1000, 1) -> 54.5
A10: Курская область | B10: ЦФО | C10: 215.1 | D10: 7.5 | E10: 83.6 | F10: 33.7 | G10: 40.4 | I10: 1068 | J10: =ROUND(F10/I10*1000, 1) -> 31.6
A11: Липецкая область | B11: ЦФО | C11: 217.1 | D11: 33.4 | E11: 72.7 | F11: 53.3 | G11: 73.4 | I11: 1117 | J11: =ROUND(F11/I11*1000, 1) -> 47.7
A12: Московская область | B12: ЦФО | C12: 2793.4 | D12: 350 | E12: 1207 | F12: 272.2 | G12: 22.6 | I12: 8524 | J12: =ROUND(F12/I12*1000, 1) -> 31.9
A13: Орловская область | B13: ЦФО | C13: 77.4 | D13: 8.5 | E13: 49.3 | F13: 44 | G13: 89.1 | I13: 706 | J13: =ROUND(F13/I13*1000, 1) -> 62.3
A14: Рязанская область | B14: ЦФО | C14: 164.8 | D14: 5.5 | E14: 118.3 | F14: 25.7 | G14: 21.7 | I14: 1072 | J14: =ROUND(F14/I14*1000, 1) -> 24
... A87: Чукотский автономный округ | B87: ДФО | C87: 102.3 | D87: 0.4 | E87: 99.1 | F87: 2.9 | G87: 2.9 | I87: 48 | J87: =ROUND(F87/I87*1000, 1) -> 60.4

Sheet Сводная таблица 1

Sheet raw_pollution
A1: Случаи высокого и экстремально высокого загрязнения по регионам, I полугодие 2022 г.
A2: год | B2: регион | C2: кол-во случаев высокого загрязнения | D2: кол-во случаев экстремально высокого загрязнения | E2: всего случаев
A3: 2022 | B3: Алтайский край | C3: 0 | D3: 1 | E3: 1
A4: 2022 | B4: Архангельская область | C4: 2 | D4: 2 | E4: 4
A5: 2022 | B5: Белгородская область | C5: 2 | D5: 0 | E5: 2
A6: 2022 | B6: Владимирская область | C6: 9 | D6: 0 | E6: 9
A7: 2022 | B7: Вологодская область | C7: 12 | D7: 2 | E7: 14
A8: 2022 | B8: Москва | C8: 50 | D8: 0 | E8: 50
A9: 2022 | B9: Санкт-Петербург | C9: 4 | D9: 0 | E9: 4
A10: 2022 | B10: Забайкальский край | C10: 5 | D10: 1 | E10: 6
A11: 2022 | B11: Ивановская область | C11: 2 | D11: 0 | E11: 2
A12: 2022 | B12: Кабардино-Балкарская Республика | C12: 1 | D12: 0 | E12: 1
A13: 2022 | B13: Кемеровская область | C13: 8 | D13: 1 | E13: 9
A14: 2022 | B14: Костромская область | C14: 0 | D14: 1 | E14: 1
... A48: 2022 | B48: Ямало-Ненецкий автономный округ | C48: 30 | D48: 16 | E48: 46
B49: Итого по регионам | C49: 967 | D49: 251 | E49: 1218

Sheet raw_pollutants
A1: Поступление загрязняющих веществ со сточными водами, 1993–2022 гг.
A2: год | B2: объем сброса сточных вод, млрд м3 | C2: в составе сточных вод сброшено
C3: сульфатов, млн т | D3: хлоридов, млн т | E3: нитратов, тыс. т | F3: жиров и масел, тыс. т | G3: фенола, т | H3: свинца, т | I3: ртути, т
A4: 1993 | B4: 68.2 | C4: 5.7 | D4: 8.4 | E4: 140.6 | F4: 30.9 | G4: 130.6 | H4: 118.1 | I4: 12.4
A5: 1994 | B5: 60.2 | C5: 3.7 | D5: 8.8 | E5: 137.1 | F5: 35.2 | G5: 99.3 | H5: 84.1 | I5: 1
A6: 1995 | B6: 59.9 | C6: 3.7 | D6: 8.6 | E6: 179.6 | F6: 25.1 | G6: 85.9 | H6: 50.5 | I6: 0.6
A7: 1996 | B7: 58.9 | C7: 2.7 | D7: 3.2 | E7: 188.1 | F7: 21.6 | G7: 78.7 | H7: 39.9 | I7: 15.4
A8: 1997 | B8: 59.3 | C8: 3.4 | D8: 4.1 | E8: 196.2 | F8: 23.3 | G8: 65.5 | H8: 39.9 | I8: 0.6
A9: 1998 | B9: 55.7 | C9: 3.1 | D9: 8 | E9: 181.7 | F9: 20.3 | G9: 62 | H9: 43.3 | I9: 0.4
A10: 1999 | B10: 54.8 | C10: 2.7 | D10: 7 | E10: 224.4 | F10: 16.5 | G10: 60.6 | H10: 33.9 | I10: 0.2
A11: 2000 | B11: 55.6 | C11: 2.7 | D11: 7.3 | E11: 208.5 | F11: 15.2 | G11: 66.6 | H11: 34.9 | I11: 0.2
A12: 2001 | B12: 54.7 | C12: 2.6 | D12: 7.7 | E12: 201.3 | F12: 13.8 | G12: 53.1 | H12: 26.7 | I12: 0.2
A13: 2002 | B13: 54.7 | C13: 3.1 | D13: 8.1 | E13: 237.2 | F13: 14.9 | G13: 53.6 | H13: 25 | I13: 0.2
A14: 2003 | B14: 52.3 | C14: 2.4 | D14: 7.5 | E14: 274.4 | F14: 13 | G14: 47.7 | H14: 23.5 | I14: 0.2
A15: 2004 | B15: 51.3 | C15: 2.4 | D15: 6.8 | E15: 288.2 | F15: 9.1 | G15: 46.2 | H15: 16.8 | I15: 0.1
... A33: 2022 | B33: 36.2 | C33: 1.6 | D33: 6.2 | E33: 360.5 | F33: 0.4 | G33: 20 | H33: 8.6 | I33: 0.01

Sheet raw_basins
A1: Сброс загрязненных сточных вод по бассейнам рек и морей, 1993–2022 гг., млрд м3
A2: год | B2: всего | C2: Бассейн Балтийского моря | D2: в том числе бассейн Невы | E2: Бассейн Черного моря | F2: Бассейн Азовского моря | G2: в том числе бассейн Дона | H2: в том числе бассейн Кубани | I2: Бассейн Каспийского моря | J2: в том числе бассейн Волги | K2: Бассейн Карского моря | L2: в том числе бассейн Енисея | M2: в том числе бассейн Оби | N2: Бассейн Белого моря
A3: 1993 | B3: 27.2 | C3: 2.5 | D3: 0.6 | E3: 0.4 | F3: 4.3 | G3: 1.4 | H3: 1.6 | I3: 12.1 | J3: 10.2 | K3: 5.3 | L3: 2 | M3: 3 | N3: 1
A4: 1994 | B4: 24.6 | C4: 2.3 | D4: 0.6 | E4: 0.4 | F4: 3.2 | G4: 1.2 | H4: 1.3 | I4: 11 | J4: 9.6 | K4: 5 | L4: 1.8 | M4: 2.9 | N4: 0.9
A5: 1995 | B5: 24.5 | C5: 2.3 | D5: 0.5 | E5: 0.4 | F5: 3.5 | G5: 1.3 | H5: 1.3 | I5: 10.4 | J5: 9.2 | K5: 5.2 | L5: 1.8 | M5: 3.1 | N5: 0.9
A6: 1996 | B6: 22.4 | C6: 2.2 | D6: 0.5 | E6: 0.3 | F6: 3.1 | G6: 1.4 | H6: 1 | I6: 9.8 | J6: 8.7 | K6: 4.7 | L6: 1.7 | M6: 2.7 | N6: 0.8
A7: 1997 | B7: 23 | C7: 2.2 | D7: 0.4 | E7: 0.3 | F7: 3.8 | G7: 1.2 | H7: 1.6 | I7: 9.8 | J7: 8.7 | K7: 4.4 | L7: 1.5 | M7: 2.6 | N7: 0.8
A8: 1998 | B8: 22 | C8: 2.2 | D8: 0.5 | E8: 0.3 | F8: 3.2 | G8: 1.1 | H8: 1.3 | I8: 9.5 | J8: 8.6 | K8: 4.2 | L8: 1.4 | M8: 2.5 | N8: 0.8
A9: 1999 | B9: 20.7 | C9: 2.2 | D9: 0.5 | E9: 0.3 | F9: 2.5 | G9: 1.1 | H9: 0.7 | I9: 9.1 | J9: 8.4 | K9: 4.1 | L9: 1.4 | M9: 2.5 | N9: 0.8
A10: 2000 | B10: 20.3 | C10: 2.2 | D10: 0.5 | E10: 0.3 | F10: 2 | G10: 0.8 | H10: 0.6 | I10: 9.2 | J10: 8.3 | K10: 4.2 | L10: 1.4 | M10: 2.6 | N10: 0.9
A11: 2001 | B11: 19.8 | C11: 2.1 | D11: 0.4 | E11: 0.3 | F11: 1.9 | G11: 0.7 | H11: 0.7 | I11: 8.9 | J11: 8.1 | K11: 4.2 | L11: 1.4 | M11: 2.6 | N11: 0.9
A12: 2002 | B12: 19.8 | C12: 2 | D12: 0.4 | E12: 0.2 | F12: 2 | G12: 0.9 | H12: 0.6 | I12: 9.2 | J12: 8.5 | K12: 4.1 | L12: 1.3 | M12: 2.5 | N12: 0.8
A13: 2003 | B13: 19 | C13: 2 | D13: 0.4 | E13: 0.2 | F13: 2.1 | G13: 0.8 | H13: 0.7 | I13: 8.4 | J13: 7.7 | K13: 4 | L13: 1.3 | M13: 2.5 | N13: 0.8
A14: 2004 | B14: 18.5 | C14: 2 | D14: 0.4 | E14: 0.2 | F14: 2.1 | G14: 0.7 | H14: 0.7 | I14: 8.3 | J14: 7.6 | K14: 3.8 | L14: 1.2 | M14: 2.4 | N14: 0.8
... A32: 2022 | B32: 11.3 | C32: 1.5 | D32: 0.2 | E32: 0.2 | F32: 1.4 | G32: 0.5 | H32: 0.9 | I32: 4.7 | J32: 4.3 | K32: 2.2 | L32: 0.7 | M32: 1.4 | N32: 0.4

Sheet raw_industry
A1: Сброс загрязненных сточных вод по видам экономической деятельности, 2017–2022 гг. (млн. куб. м.)
A2: вид деятельности | B2: 2017 | C2: 2018 | D2: 2019 | E2: 2020 | F2: 2021 | G2: 2022
A3: Всего | B3: 13590.6 | C3: 13137.8 | D3: 12602.2 | E3: 11797.3 | F3: 11611.5 | G3: 11325.8
A4: Сельское и лесное хозяйство | B4: 740.2 | C4: 748.3 | D4: 679.8 | E4: 479.8 | F4: 614.5 | G4: 763.8
A5: Добыча полезных ископаемых | B5: 832.2 | C5: 784.5 | D5: 687.6 | E5: 496 | F5: 447.9 | G5: 404
A6: Обрабатывающие производства | B6: 2402.6 | C6: 2275.9 | D6: 2088.6 | E6: 1877.3 | F6: 1723.4 | G6: 1704.9
A7: Энергетика | B7: 1001.1 | C7: 888.5 | D7: 933.2 | E7: 811.8 | F7: 822.6 | G7: 804.6
A8: Водоснабжение и водоотведение | B8: 8251.7 | C8: 8100 | D8: 7922.2 | E8: 7880.6 | F8: 7760.9 | G8: 7406.3
A9: Добыча угля | B9: 354.1 | C9: 340 | D9: 283.1 | E9: 252.7 | F9: 215.3 | G9: 195.2
A10: Металлургия | B10: 691.9 | C10: 637.2 | D10: 447.8 | E10: 404.8 | F10: 365.6 | G10: 389.7
A11: Химическая промышленность | B11: 515 | C11: 499.1 | D11: 480.2 | E11: 462.7 | F11: 425.9 | G11: 388
A12: Производство бумаги | B12: 855.5 | C12: 796.3 | D12: 817.2 | E12: 699.2 | F12: 632.2 | G12: 642.3

Sheet Сводная таблица 3
